 * Serving Flask app 'titanic' (lazy loading)
 * Environment: production
   WARNING: This is a development server. Do not use it in a production deployment.
   Use a production WSGI server instead.
 * Debug mode: off
/usr/local/lib/python3.7/dist-packages/numba/errors.py:137: UserWarning: Insufficiently recent colorama version found. Numba requires colorama >= 0.3.9
  warnings.warn(msg)
IPython could not be loaded!
2021-08-10 13:43:50,507 werkzeug WARNING  * Running on all addresses.
   WARNING: This is a development server. Do not use it in a production deployment.
2021-08-10 13:43:50,507 werkzeug INFO  * Running on http://10.0.153.117:5600/ (Press CTRL+C to quit)
 * Serving Flask app 'titanic' (lazy loading)
 * Environment: production
   WARNING: This is a development server. Do not use it in a production deployment.
   Use a production WSGI server instead.
 * Debug mode: off
/usr/local/lib/python3.7/dist-packages/numba/errors.py:137: UserWarning: Insufficiently recent colorama version found. Numba requires colorama >= 0.3.9
  warnings.warn(msg)
IPython could not be loaded!
2021-08-10 14:55:31,696 werkzeug WARNING  * Running on all addresses.
   WARNING: This is a development server. Do not use it in a production deployment.
2021-08-10 14:55:31,696 werkzeug INFO  * Running on http://10.0.153.117:5600/ (Press CTRL+C to quit)
   Pclass                                          Name  ... Cabin  Embarked
0       3                              Kelly, Mr. James  ...   NaN         Q
1       3              Wilkes, Mrs. James (Ellen Needs)  ...   NaN         S
2       2                     Myles, Mr. Thomas Francis  ...   NaN         Q
3       3                              Wirz, Mr. Albert  ...   NaN         S
4       3  Hirvonen, Mrs. Alexander (Helga E Lindqvist)  ...   NaN         S

[5 rows x 10 columns]
AutoML directory: AutoML_titanic
The task is binary_classification with evaluation metric logloss
AutoML will use algorithms: ['Baseline', 'Linear', 'Decision Tree', 'Random Forest', 'Xgboost', 'Neural Network']
AutoML will ensemble availabe models
AutoML steps: ['simple_algorithms', 'default_algorithms', 'ensemble']
* Step simple_algorithms will try to check up to 3 models
1_Baseline logloss 0.693147 trained in 0.43 seconds
ntree_limit is deprecated, use `iteration_range` or model slicing instead.
An input array is constant; the correlation coefficient is not defined.
2021-08-10 14:57:27,873 werkzeug INFO 127.0.0.1 - - [10/Aug/2021 14:57:27] "GET /api/train HTTP/1.1" 200 -
/usr/local/lib/python3.7/dist-packages/numba/errors.py:137: UserWarning: Insufficiently recent colorama version found. Numba requires colorama >= 0.3.9
  warnings.warn(msg)
IPython could not be loaded!
ntree_limit is deprecated, use `iteration_range` or model slicing instead.
ntree_limit is deprecated, use `iteration_range` or model slicing instead.
ntree_limit is deprecated, use `iteration_range` or model slicing instead.
ntree_limit is deprecated, use `iteration_range` or model slicing instead.
ntree_limit is deprecated, use `iteration_range` or model slicing instead.
ntree_limit is deprecated, use `iteration_range` or model slicing instead.
ntree_limit is deprecated, use `iteration_range` or model slicing instead.
ntree_limit is deprecated, use `iteration_range` or model slicing instead.
ntree_limit is deprecated, use `iteration_range` or model slicing instead.
ntree_limit is deprecated, use `iteration_range` or model slicing instead.
/usr/local/lib/python3.7/dist-packages/numba/errors.py:137: UserWarning: Insufficiently recent colorama version found. Numba requires colorama >= 0.3.9
  warnings.warn(msg)
IPython could not be loaded!
ntree_limit is deprecated, use `iteration_range` or model slicing instead.
ntree_limit is deprecated, use `iteration_range` or model slicing instead.
ntree_limit is deprecated, use `iteration_range` or model slicing instead.
ntree_limit is deprecated, use `iteration_range` or model slicing instead.
ntree_limit is deprecated, use `iteration_range` or model slicing instead.
ntree_limit is deprecated, use `iteration_range` or model slicing instead.
ntree_limit is deprecated, use `iteration_range` or model slicing instead.
ntree_limit is deprecated, use `iteration_range` or model slicing instead.
ntree_limit is deprecated, use `iteration_range` or model slicing instead.
ntree_limit is deprecated, use `iteration_range` or model slicing instead.
ntree_limit is deprecated, use `iteration_range` or model slicing instead.
ntree_limit is deprecated, use `iteration_range` or model slicing instead.
ntree_limit is deprecated, use `iteration_range` or model slicing instead.
ntree_limit is deprecated, use `iteration_range` or model slicing instead.
ntree_limit is deprecated, use `iteration_range` or model slicing instead.
/usr/local/lib/python3.7/dist-packages/numba/errors.py:137: UserWarning: Insufficiently recent colorama version found. Numba requires colorama >= 0.3.9
  warnings.warn(msg)
IPython could not be loaded!
ntree_limit is deprecated, use `iteration_range` or model slicing instead.
ntree_limit is deprecated, use `iteration_range` or model slicing instead.
ntree_limit is deprecated, use `iteration_range` or model slicing instead.
ntree_limit is deprecated, use `iteration_range` or model slicing instead.
ntree_limit is deprecated, use `iteration_range` or model slicing instead.
ntree_limit is deprecated, use `iteration_range` or model slicing instead.
ntree_limit is deprecated, use `iteration_range` or model slicing instead.
ntree_limit is deprecated, use `iteration_range` or model slicing instead.
ntree_limit is deprecated, use `iteration_range` or model slicing instead.
ntree_limit is deprecated, use `iteration_range` or model slicing instead.
/usr/local/lib/python3.7/dist-packages/numba/errors.py:137: UserWarning: Insufficiently recent colorama version found. Numba requires colorama >= 0.3.9
  warnings.warn(msg)
IPython could not be loaded!
ntree_limit is deprecated, use `iteration_range` or model slicing instead.
ntree_limit is deprecated, use `iteration_range` or model slicing instead.
ntree_limit is deprecated, use `iteration_range` or model slicing instead.
ntree_limit is deprecated, use `iteration_range` or model slicing instead.
ntree_limit is deprecated, use `iteration_range` or model slicing instead.
ntree_limit is deprecated, use `iteration_range` or model slicing instead.
ntree_limit is deprecated, use `iteration_range` or model slicing instead.
ntree_limit is deprecated, use `iteration_range` or model slicing instead.
ntree_limit is deprecated, use `iteration_range` or model slicing instead.
ntree_limit is deprecated, use `iteration_range` or model slicing instead.
2021-08-10 15:09:16,476 werkzeug INFO 127.0.0.1 - - [10/Aug/2021 15:09:16] "GET /api/train HTTP/1.1" 200 -
2021-08-10 15:11:37,404 werkzeug INFO 127.0.0.1 - - [10/Aug/2021 15:11:37] "GET /api/train HTTP/1.1" 200 -
2021-08-10 15:12:58,600 werkzeug INFO 127.0.0.1 - - [10/Aug/2021 15:12:58] "[33mGET /api/predictvalue HTTP/1.1[0m" 404 -
2021-08-10 15:13:37,156 werkzeug INFO 127.0.0.1 - - [10/Aug/2021 15:13:37] "[33mGET /api/predictvalue HTTP/1.1[0m" 404 -
2021-08-10 15:22:23,624 werkzeug INFO 127.0.0.1 - - [10/Aug/2021 15:22:23] "GET /api/preObject HTTP/1.1" 200 -
/usr/local/lib/python3.7/dist-packages/joblib/externals/loky/backend/resource_tracker.py:320: UserWarning: resource_tracker: There appear to be 6 leaked semlock objects to clean up at shutdown
  (len(rtype_registry), rtype))
/usr/local/lib/python3.7/dist-packages/joblib/externals/loky/backend/resource_tracker.py:320: UserWarning: resource_tracker: There appear to be 6 leaked folder objects to clean up at shutdown
  (len(rtype_registry), rtype))
 * Serving Flask app 'titanic' (lazy loading)
 * Environment: production
   WARNING: This is a development server. Do not use it in a production deployment.
   Use a production WSGI server instead.
 * Debug mode: off
/usr/local/lib/python3.7/dist-packages/numba/errors.py:137: UserWarning: Insufficiently recent colorama version found. Numba requires colorama >= 0.3.9
  warnings.warn(msg)
IPython could not be loaded!
2021-08-11 06:48:53,521 werkzeug WARNING  * Running on all addresses.
   WARNING: This is a development server. Do not use it in a production deployment.
2021-08-11 06:48:53,521 werkzeug INFO  * Running on http://10.0.153.117:5600/ (Press CTRL+C to quit)
2021-08-11 06:50:25,397 werkzeug INFO 127.0.0.1 - - [11/Aug/2021 06:50:25] "GET /api/train HTTP/1.1" 200 -
2021-08-11 06:51:00,432 supervised.exceptions ERROR Cannot load AutoML directory. [Errno 2] No such file or directory: '/opt/python/Titanic_Model/AutoML_titanic/params.json'
2021-08-11 06:51:00,432 titanic ERROR Exception on /api/preObject [GET]
Traceback (most recent call last):
  File "/var/lib/jenkins/.local/lib/python3.7/site-packages/supervised/base_automl.py", line 133, in load
    params = json.load(open(os.path.join(path, "params.json")))
FileNotFoundError: [Errno 2] No such file or directory: '/opt/python/Titanic_Model/AutoML_titanic/params.json'

During handling of the above exception, another exception occurred:

Traceback (most recent call last):
  File "/usr/local/lib/python3.7/dist-packages/flask/app.py", line 2070, in wsgi_app
    response = self.full_dispatch_request()
  File "/usr/local/lib/python3.7/dist-packages/flask/app.py", line 1515, in full_dispatch_request
    rv = self.handle_user_exception(e)
  File "/usr/local/lib/python3.7/dist-packages/flask/app.py", line 1513, in full_dispatch_request
    rv = self.dispatch_request()
  File "/usr/local/lib/python3.7/dist-packages/flask/app.py", line 1499, in dispatch_request
    return self.ensure_sync(self.view_functions[rule.endpoint])(**req.view_args)
  File "titanic.py", line 35, in predictobject
    predictions = automl.predict(test)
  File "/var/lib/jenkins/.local/lib/python3.7/site-packages/supervised/automl.py", line 356, in predict
    return self._predict(X)
  File "/var/lib/jenkins/.local/lib/python3.7/site-packages/supervised/base_automl.py", line 1306, in _predict
    predictions = self._base_predict(X)
  File "/var/lib/jenkins/.local/lib/python3.7/site-packages/supervised/base_automl.py", line 1238, in _base_predict
    self.load(self.results_path)
  File "/var/lib/jenkins/.local/lib/python3.7/site-packages/supervised/base_automl.py", line 219, in load
    raise AutoMLException(f"Cannot load AutoML directory. {str(e)}")
supervised.exceptions.AutoMLException: Cannot load AutoML directory. [Errno 2] No such file or directory: '/opt/python/Titanic_Model/AutoML_titanic/params.json'
2021-08-11 06:51:00,455 werkzeug INFO 127.0.0.1 - - [11/Aug/2021 06:51:00] "[35m[1mGET /api/preObject HTTP/1.1[0m" 500 -
2021-08-11 06:51:27,727 supervised.exceptions ERROR Cannot load AutoML directory. [Errno 2] No such file or directory: '/opt/python/Titanic_Model/AutoML_titanic/params.json'
2021-08-11 06:51:27,728 titanic ERROR Exception on /api/preObject [GET]
Traceback (most recent call last):
  File "/var/lib/jenkins/.local/lib/python3.7/site-packages/supervised/base_automl.py", line 133, in load
    params = json.load(open(os.path.join(path, "params.json")))
FileNotFoundError: [Errno 2] No such file or directory: '/opt/python/Titanic_Model/AutoML_titanic/params.json'

During handling of the above exception, another exception occurred:

Traceback (most recent call last):
  File "/usr/local/lib/python3.7/dist-packages/flask/app.py", line 2070, in wsgi_app
    response = self.full_dispatch_request()
  File "/usr/local/lib/python3.7/dist-packages/flask/app.py", line 1515, in full_dispatch_request
    rv = self.handle_user_exception(e)
  File "/usr/local/lib/python3.7/dist-packages/flask/app.py", line 1513, in full_dispatch_request
    rv = self.dispatch_request()
  File "/usr/local/lib/python3.7/dist-packages/flask/app.py", line 1499, in dispatch_request
    return self.ensure_sync(self.view_functions[rule.endpoint])(**req.view_args)
  File "titanic.py", line 35, in predictobject
    predictions = automl.predict(test)
  File "/var/lib/jenkins/.local/lib/python3.7/site-packages/supervised/automl.py", line 356, in predict
    return self._predict(X)
  File "/var/lib/jenkins/.local/lib/python3.7/site-packages/supervised/base_automl.py", line 1306, in _predict
    predictions = self._base_predict(X)
  File "/var/lib/jenkins/.local/lib/python3.7/site-packages/supervised/base_automl.py", line 1238, in _base_predict
    self.load(self.results_path)
  File "/var/lib/jenkins/.local/lib/python3.7/site-packages/supervised/base_automl.py", line 219, in load
    raise AutoMLException(f"Cannot load AutoML directory. {str(e)}")
supervised.exceptions.AutoMLException: Cannot load AutoML directory. [Errno 2] No such file or directory: '/opt/python/Titanic_Model/AutoML_titanic/params.json'
2021-08-11 06:51:27,728 werkzeug INFO 127.0.0.1 - - [11/Aug/2021 06:51:27] "[35m[1mGET /api/preObject HTTP/1.1[0m" 500 -
2021-08-11 06:54:47,241 supervised.exceptions ERROR Cannot load AutoML directory. [Errno 2] No such file or directory: '/opt/python/Titanic_Model/AutoML_titanic/params.json'
2021-08-11 06:54:47,241 titanic ERROR Exception on /api/preObject [GET]
Traceback (most recent call last):
  File "/var/lib/jenkins/.local/lib/python3.7/site-packages/supervised/base_automl.py", line 133, in load
    params = json.load(open(os.path.join(path, "params.json")))
FileNotFoundError: [Errno 2] No such file or directory: '/opt/python/Titanic_Model/AutoML_titanic/params.json'

During handling of the above exception, another exception occurred:

Traceback (most recent call last):
  File "/usr/local/lib/python3.7/dist-packages/flask/app.py", line 2070, in wsgi_app
    response = self.full_dispatch_request()
  File "/usr/local/lib/python3.7/dist-packages/flask/app.py", line 1515, in full_dispatch_request
    rv = self.handle_user_exception(e)
  File "/usr/local/lib/python3.7/dist-packages/flask/app.py", line 1513, in full_dispatch_request
    rv = self.dispatch_request()
  File "/usr/local/lib/python3.7/dist-packages/flask/app.py", line 1499, in dispatch_request
    return self.ensure_sync(self.view_functions[rule.endpoint])(**req.view_args)
  File "titanic.py", line 35, in predictobject
    predictions = automl.predict(test)
  File "/var/lib/jenkins/.local/lib/python3.7/site-packages/supervised/automl.py", line 356, in predict
    return self._predict(X)
  File "/var/lib/jenkins/.local/lib/python3.7/site-packages/supervised/base_automl.py", line 1306, in _predict
    predictions = self._base_predict(X)
  File "/var/lib/jenkins/.local/lib/python3.7/site-packages/supervised/base_automl.py", line 1238, in _base_predict
    self.load(self.results_path)
  File "/var/lib/jenkins/.local/lib/python3.7/site-packages/supervised/base_automl.py", line 219, in load
    raise AutoMLException(f"Cannot load AutoML directory. {str(e)}")
supervised.exceptions.AutoMLException: Cannot load AutoML directory. [Errno 2] No such file or directory: '/opt/python/Titanic_Model/AutoML_titanic/params.json'
2021-08-11 06:54:47,242 werkzeug INFO 127.0.0.1 - - [11/Aug/2021 06:54:47] "[35m[1mGET /api/preObject HTTP/1.1[0m" 500 -
2021-08-11 07:06:23,594 supervised.exceptions ERROR Cannot load AutoML directory. [Errno 2] No such file or directory: '/opt/python/Titanic_Model/AutoML_titanic/params.json'
2021-08-11 07:06:23,594 titanic ERROR Exception on /api/preObject [GET]
Traceback (most recent call last):
  File "/var/lib/jenkins/.local/lib/python3.7/site-packages/supervised/base_automl.py", line 133, in load
    params = json.load(open(os.path.join(path, "params.json")))
FileNotFoundError: [Errno 2] No such file or directory: '/opt/python/Titanic_Model/AutoML_titanic/params.json'

During handling of the above exception, another exception occurred:

Traceback (most recent call last):
  File "/usr/local/lib/python3.7/dist-packages/flask/app.py", line 2070, in wsgi_app
    response = self.full_dispatch_request()
  File "/usr/local/lib/python3.7/dist-packages/flask/app.py", line 1515, in full_dispatch_request
    rv = self.handle_user_exception(e)
  File "/usr/local/lib/python3.7/dist-packages/flask/app.py", line 1513, in full_dispatch_request
    rv = self.dispatch_request()
  File "/usr/local/lib/python3.7/dist-packages/flask/app.py", line 1499, in dispatch_request
    return self.ensure_sync(self.view_functions[rule.endpoint])(**req.view_args)
  File "titanic.py", line 35, in predictobject
    predictions = automl.predict(test)
  File "/var/lib/jenkins/.local/lib/python3.7/site-packages/supervised/automl.py", line 356, in predict
    return self._predict(X)
  File "/var/lib/jenkins/.local/lib/python3.7/site-packages/supervised/base_automl.py", line 1306, in _predict
    predictions = self._base_predict(X)
  File "/var/lib/jenkins/.local/lib/python3.7/site-packages/supervised/base_automl.py", line 1238, in _base_predict
    self.load(self.results_path)
  File "/var/lib/jenkins/.local/lib/python3.7/site-packages/supervised/base_automl.py", line 219, in load
    raise AutoMLException(f"Cannot load AutoML directory. {str(e)}")
supervised.exceptions.AutoMLException: Cannot load AutoML directory. [Errno 2] No such file or directory: '/opt/python/Titanic_Model/AutoML_titanic/params.json'
2021-08-11 07:06:23,595 werkzeug INFO 127.0.0.1 - - [11/Aug/2021 07:06:23] "[35m[1mGET /api/preObject HTTP/1.1[0m" 500 -
 * Serving Flask app 'titanic' (lazy loading)
 * Environment: production
   WARNING: This is a development server. Do not use it in a production deployment.
   Use a production WSGI server instead.
 * Debug mode: off
/usr/local/lib/python3.7/dist-packages/numba/errors.py:137: UserWarning: Insufficiently recent colorama version found. Numba requires colorama >= 0.3.9
  warnings.warn(msg)
IPython could not be loaded!
Traceback (most recent call last):
  File "titanic.py", line 56, in <module>
    app.run(host='0.0.0.0',port=5600)
  File "/usr/local/lib/python3.7/dist-packages/flask/app.py", line 922, in run
    run_simple(t.cast(str, host), port, self, **options)
  File "/usr/local/lib/python3.7/dist-packages/werkzeug/serving.py", line 1008, in run_simple
    inner()
  File "/usr/local/lib/python3.7/dist-packages/werkzeug/serving.py", line 957, in inner
    fd=fd,
  File "/usr/local/lib/python3.7/dist-packages/werkzeug/serving.py", line 781, in make_server
    host, port, app, request_handler, passthrough_errors, ssl_context, fd=fd
  File "/usr/local/lib/python3.7/dist-packages/werkzeug/serving.py", line 686, in __init__
    super().__init__(server_address, handler)  # type: ignore
  File "/usr/lib/python3.7/socketserver.py", line 452, in __init__
    self.server_bind()
  File "/usr/lib/python3.7/http/server.py", line 137, in server_bind
    socketserver.TCPServer.server_bind(self)
  File "/usr/lib/python3.7/socketserver.py", line 466, in server_bind
    self.socket.bind(self.server_address)
OSError: [Errno 98] Address already in use
2021-08-11 07:09:57,120 werkzeug INFO 127.0.0.1 - - [11/Aug/2021 07:09:57] "GET /api/train HTTP/1.1" 200 -
2021-08-11 07:10:16,321 supervised.exceptions ERROR Cannot load AutoML directory. [Errno 2] No such file or directory: '/opt/python/Titanic_Model/AutoML_titanic/params.json'
2021-08-11 07:10:16,321 titanic ERROR Exception on /api/preObject [GET]
Traceback (most recent call last):
  File "/var/lib/jenkins/.local/lib/python3.7/site-packages/supervised/base_automl.py", line 133, in load
    params = json.load(open(os.path.join(path, "params.json")))
FileNotFoundError: [Errno 2] No such file or directory: '/opt/python/Titanic_Model/AutoML_titanic/params.json'

During handling of the above exception, another exception occurred:

Traceback (most recent call last):
  File "/usr/local/lib/python3.7/dist-packages/flask/app.py", line 2070, in wsgi_app
    response = self.full_dispatch_request()
  File "/usr/local/lib/python3.7/dist-packages/flask/app.py", line 1515, in full_dispatch_request
    rv = self.handle_user_exception(e)
  File "/usr/local/lib/python3.7/dist-packages/flask/app.py", line 1513, in full_dispatch_request
    rv = self.dispatch_request()
  File "/usr/local/lib/python3.7/dist-packages/flask/app.py", line 1499, in dispatch_request
    return self.ensure_sync(self.view_functions[rule.endpoint])(**req.view_args)
  File "titanic.py", line 35, in predictobject
    predictions = automl.predict(test)
  File "/var/lib/jenkins/.local/lib/python3.7/site-packages/supervised/automl.py", line 356, in predict
    return self._predict(X)
  File "/var/lib/jenkins/.local/lib/python3.7/site-packages/supervised/base_automl.py", line 1306, in _predict
    predictions = self._base_predict(X)
  File "/var/lib/jenkins/.local/lib/python3.7/site-packages/supervised/base_automl.py", line 1238, in _base_predict
    self.load(self.results_path)
  File "/var/lib/jenkins/.local/lib/python3.7/site-packages/supervised/base_automl.py", line 219, in load
    raise AutoMLException(f"Cannot load AutoML directory. {str(e)}")
supervised.exceptions.AutoMLException: Cannot load AutoML directory. [Errno 2] No such file or directory: '/opt/python/Titanic_Model/AutoML_titanic/params.json'
2021-08-11 07:10:16,322 werkzeug INFO 127.0.0.1 - - [11/Aug/2021 07:10:16] "[35m[1mGET /api/preObject HTTP/1.1[0m" 500 -
2021-08-11 07:10:46,799 supervised.exceptions ERROR Cannot load AutoML directory. [Errno 2] No such file or directory: '/opt/python/Titanic_Model/AutoML_titanic/params.json'
2021-08-11 07:10:46,799 titanic ERROR Exception on /api/preObject [GET]
Traceback (most recent call last):
  File "/var/lib/jenkins/.local/lib/python3.7/site-packages/supervised/base_automl.py", line 133, in load
    params = json.load(open(os.path.join(path, "params.json")))
FileNotFoundError: [Errno 2] No such file or directory: '/opt/python/Titanic_Model/AutoML_titanic/params.json'

During handling of the above exception, another exception occurred:

Traceback (most recent call last):
  File "/usr/local/lib/python3.7/dist-packages/flask/app.py", line 2070, in wsgi_app
    response = self.full_dispatch_request()
  File "/usr/local/lib/python3.7/dist-packages/flask/app.py", line 1515, in full_dispatch_request
    rv = self.handle_user_exception(e)
  File "/usr/local/lib/python3.7/dist-packages/flask/app.py", line 1513, in full_dispatch_request
    rv = self.dispatch_request()
  File "/usr/local/lib/python3.7/dist-packages/flask/app.py", line 1499, in dispatch_request
    return self.ensure_sync(self.view_functions[rule.endpoint])(**req.view_args)
  File "titanic.py", line 35, in predictobject
    predictions = automl.predict(test)
  File "/var/lib/jenkins/.local/lib/python3.7/site-packages/supervised/automl.py", line 356, in predict
    return self._predict(X)
  File "/var/lib/jenkins/.local/lib/python3.7/site-packages/supervised/base_automl.py", line 1306, in _predict
    predictions = self._base_predict(X)
  File "/var/lib/jenkins/.local/lib/python3.7/site-packages/supervised/base_automl.py", line 1238, in _base_predict
    self.load(self.results_path)
  File "/var/lib/jenkins/.local/lib/python3.7/site-packages/supervised/base_automl.py", line 219, in load
    raise AutoMLException(f"Cannot load AutoML directory. {str(e)}")
supervised.exceptions.AutoMLException: Cannot load AutoML directory. [Errno 2] No such file or directory: '/opt/python/Titanic_Model/AutoML_titanic/params.json'
2021-08-11 07:10:46,799 werkzeug INFO 127.0.0.1 - - [11/Aug/2021 07:10:46] "[35m[1mGET /api/preObject HTTP/1.1[0m" 500 -
 * Serving Flask app 'titanic' (lazy loading)
 * Environment: production
   WARNING: This is a development server. Do not use it in a production deployment.
   Use a production WSGI server instead.
 * Debug mode: off
/usr/local/lib/python3.7/dist-packages/numba/errors.py:137: UserWarning: Insufficiently recent colorama version found. Numba requires colorama >= 0.3.9
  warnings.warn(msg)
IPython could not be loaded!
Traceback (most recent call last):
  File "titanic.py", line 56, in <module>
    app.run(host='0.0.0.0',port=5600)
  File "/usr/local/lib/python3.7/dist-packages/flask/app.py", line 922, in run
    run_simple(t.cast(str, host), port, self, **options)
  File "/usr/local/lib/python3.7/dist-packages/werkzeug/serving.py", line 1008, in run_simple
    inner()
  File "/usr/local/lib/python3.7/dist-packages/werkzeug/serving.py", line 957, in inner
    fd=fd,
  File "/usr/local/lib/python3.7/dist-packages/werkzeug/serving.py", line 781, in make_server
    host, port, app, request_handler, passthrough_errors, ssl_context, fd=fd
  File "/usr/local/lib/python3.7/dist-packages/werkzeug/serving.py", line 686, in __init__
    super().__init__(server_address, handler)  # type: ignore
  File "/usr/lib/python3.7/socketserver.py", line 452, in __init__
    self.server_bind()
  File "/usr/lib/python3.7/http/server.py", line 137, in server_bind
    socketserver.TCPServer.server_bind(self)
  File "/usr/lib/python3.7/socketserver.py", line 466, in server_bind
    self.socket.bind(self.server_address)
OSError: [Errno 98] Address already in use
2021-08-11 07:15:35,342 supervised.exceptions ERROR Cannot load AutoML directory. [Errno 2] No such file or directory: '/opt/python/Titanic_Model/AutoML_titanic/params.json'
2021-08-11 07:15:35,342 titanic ERROR Exception on /api/preObject [GET]
Traceback (most recent call last):
  File "/var/lib/jenkins/.local/lib/python3.7/site-packages/supervised/base_automl.py", line 133, in load
    params = json.load(open(os.path.join(path, "params.json")))
FileNotFoundError: [Errno 2] No such file or directory: '/opt/python/Titanic_Model/AutoML_titanic/params.json'

During handling of the above exception, another exception occurred:

Traceback (most recent call last):
  File "/usr/local/lib/python3.7/dist-packages/flask/app.py", line 2070, in wsgi_app
    response = self.full_dispatch_request()
  File "/usr/local/lib/python3.7/dist-packages/flask/app.py", line 1515, in full_dispatch_request
    rv = self.handle_user_exception(e)
  File "/usr/local/lib/python3.7/dist-packages/flask/app.py", line 1513, in full_dispatch_request
    rv = self.dispatch_request()
  File "/usr/local/lib/python3.7/dist-packages/flask/app.py", line 1499, in dispatch_request
    return self.ensure_sync(self.view_functions[rule.endpoint])(**req.view_args)
  File "titanic.py", line 35, in predictobject
    predictions = automl.predict(test)
  File "/var/lib/jenkins/.local/lib/python3.7/site-packages/supervised/automl.py", line 356, in predict
    return self._predict(X)
  File "/var/lib/jenkins/.local/lib/python3.7/site-packages/supervised/base_automl.py", line 1306, in _predict
    predictions = self._base_predict(X)
  File "/var/lib/jenkins/.local/lib/python3.7/site-packages/supervised/base_automl.py", line 1238, in _base_predict
    self.load(self.results_path)
  File "/var/lib/jenkins/.local/lib/python3.7/site-packages/supervised/base_automl.py", line 219, in load
    raise AutoMLException(f"Cannot load AutoML directory. {str(e)}")
supervised.exceptions.AutoMLException: Cannot load AutoML directory. [Errno 2] No such file or directory: '/opt/python/Titanic_Model/AutoML_titanic/params.json'
2021-08-11 07:15:35,343 werkzeug INFO 127.0.0.1 - - [11/Aug/2021 07:15:35] "[35m[1mGET /api/preObject HTTP/1.1[0m" 500 -
2021-08-11 07:16:02,450 supervised.exceptions ERROR Cannot load AutoML directory. [Errno 2] No such file or directory: '/opt/python/Titanic_Model/AutoML_titanic/params.json'
2021-08-11 07:16:02,451 titanic ERROR Exception on /api/preObject [GET]
Traceback (most recent call last):
  File "/var/lib/jenkins/.local/lib/python3.7/site-packages/supervised/base_automl.py", line 133, in load
    params = json.load(open(os.path.join(path, "params.json")))
FileNotFoundError: [Errno 2] No such file or directory: '/opt/python/Titanic_Model/AutoML_titanic/params.json'

During handling of the above exception, another exception occurred:

Traceback (most recent call last):
  File "/usr/local/lib/python3.7/dist-packages/flask/app.py", line 2070, in wsgi_app
    response = self.full_dispatch_request()
  File "/usr/local/lib/python3.7/dist-packages/flask/app.py", line 1515, in full_dispatch_request
    rv = self.handle_user_exception(e)
  File "/usr/local/lib/python3.7/dist-packages/flask/app.py", line 1513, in full_dispatch_request
    rv = self.dispatch_request()
  File "/usr/local/lib/python3.7/dist-packages/flask/app.py", line 1499, in dispatch_request
    return self.ensure_sync(self.view_functions[rule.endpoint])(**req.view_args)
  File "titanic.py", line 35, in predictobject
    predictions = automl.predict(test)
  File "/var/lib/jenkins/.local/lib/python3.7/site-packages/supervised/automl.py", line 356, in predict
    return self._predict(X)
  File "/var/lib/jenkins/.local/lib/python3.7/site-packages/supervised/base_automl.py", line 1306, in _predict
    predictions = self._base_predict(X)
  File "/var/lib/jenkins/.local/lib/python3.7/site-packages/supervised/base_automl.py", line 1238, in _base_predict
    self.load(self.results_path)
  File "/var/lib/jenkins/.local/lib/python3.7/site-packages/supervised/base_automl.py", line 219, in load
    raise AutoMLException(f"Cannot load AutoML directory. {str(e)}")
supervised.exceptions.AutoMLException: Cannot load AutoML directory. [Errno 2] No such file or directory: '/opt/python/Titanic_Model/AutoML_titanic/params.json'
2021-08-11 07:16:02,451 werkzeug INFO 127.0.0.1 - - [11/Aug/2021 07:16:02] "[35m[1mGET /api/preObject HTTP/1.1[0m" 500 -
2021-08-11 07:20:55,808 supervised.exceptions ERROR Cannot load AutoML directory. [Errno 2] No such file or directory: '/opt/python/Titanic_Model/AutoML_titanic/params.json'
2021-08-11 07:20:55,808 titanic ERROR Exception on /api/preObject [GET]
Traceback (most recent call last):
  File "/var/lib/jenkins/.local/lib/python3.7/site-packages/supervised/base_automl.py", line 133, in load
    params = json.load(open(os.path.join(path, "params.json")))
FileNotFoundError: [Errno 2] No such file or directory: '/opt/python/Titanic_Model/AutoML_titanic/params.json'

During handling of the above exception, another exception occurred:

Traceback (most recent call last):
  File "/usr/local/lib/python3.7/dist-packages/flask/app.py", line 2070, in wsgi_app
    response = self.full_dispatch_request()
  File "/usr/local/lib/python3.7/dist-packages/flask/app.py", line 1515, in full_dispatch_request
    rv = self.handle_user_exception(e)
  File "/usr/local/lib/python3.7/dist-packages/flask/app.py", line 1513, in full_dispatch_request
    rv = self.dispatch_request()
  File "/usr/local/lib/python3.7/dist-packages/flask/app.py", line 1499, in dispatch_request
    return self.ensure_sync(self.view_functions[rule.endpoint])(**req.view_args)
  File "titanic.py", line 35, in predictobject
    predictions = automl.predict(test)
  File "/var/lib/jenkins/.local/lib/python3.7/site-packages/supervised/automl.py", line 356, in predict
    return self._predict(X)
  File "/var/lib/jenkins/.local/lib/python3.7/site-packages/supervised/base_automl.py", line 1306, in _predict
    predictions = self._base_predict(X)
  File "/var/lib/jenkins/.local/lib/python3.7/site-packages/supervised/base_automl.py", line 1238, in _base_predict
    self.load(self.results_path)
  File "/var/lib/jenkins/.local/lib/python3.7/site-packages/supervised/base_automl.py", line 219, in load
    raise AutoMLException(f"Cannot load AutoML directory. {str(e)}")
supervised.exceptions.AutoMLException: Cannot load AutoML directory. [Errno 2] No such file or directory: '/opt/python/Titanic_Model/AutoML_titanic/params.json'
2021-08-11 07:20:55,809 werkzeug INFO 127.0.0.1 - - [11/Aug/2021 07:20:55] "[35m[1mGET /api/preObject HTTP/1.1[0m" 500 -
2021-08-11 07:46:36,889 supervised.exceptions ERROR Cannot load AutoML directory. [Errno 2] No such file or directory: '/opt/python/Titanic_Model/AutoML_titanic/params.json'
2021-08-11 07:46:36,890 titanic ERROR Exception on /api/preObject [GET]
Traceback (most recent call last):
  File "/var/lib/jenkins/.local/lib/python3.7/site-packages/supervised/base_automl.py", line 133, in load
    params = json.load(open(os.path.join(path, "params.json")))
FileNotFoundError: [Errno 2] No such file or directory: '/opt/python/Titanic_Model/AutoML_titanic/params.json'

During handling of the above exception, another exception occurred:

Traceback (most recent call last):
  File "/usr/local/lib/python3.7/dist-packages/flask/app.py", line 2070, in wsgi_app
    response = self.full_dispatch_request()
  File "/usr/local/lib/python3.7/dist-packages/flask/app.py", line 1515, in full_dispatch_request
    rv = self.handle_user_exception(e)
  File "/usr/local/lib/python3.7/dist-packages/flask/app.py", line 1513, in full_dispatch_request
    rv = self.dispatch_request()
  File "/usr/local/lib/python3.7/dist-packages/flask/app.py", line 1499, in dispatch_request
    return self.ensure_sync(self.view_functions[rule.endpoint])(**req.view_args)
  File "titanic.py", line 35, in predictobject
    predictions = automl.predict(test)
  File "/var/lib/jenkins/.local/lib/python3.7/site-packages/supervised/automl.py", line 356, in predict
    return self._predict(X)
  File "/var/lib/jenkins/.local/lib/python3.7/site-packages/supervised/base_automl.py", line 1306, in _predict
    predictions = self._base_predict(X)
  File "/var/lib/jenkins/.local/lib/python3.7/site-packages/supervised/base_automl.py", line 1238, in _base_predict
    self.load(self.results_path)
  File "/var/lib/jenkins/.local/lib/python3.7/site-packages/supervised/base_automl.py", line 219, in load
    raise AutoMLException(f"Cannot load AutoML directory. {str(e)}")
supervised.exceptions.AutoMLException: Cannot load AutoML directory. [Errno 2] No such file or directory: '/opt/python/Titanic_Model/AutoML_titanic/params.json'
2021-08-11 07:46:36,890 werkzeug INFO 127.0.0.1 - - [11/Aug/2021 07:46:36] "[35m[1mGET /api/preObject HTTP/1.1[0m" 500 -
2021-08-11 07:51:05,909 supervised.exceptions ERROR Cannot load AutoML directory. [Errno 2] No such file or directory: '/opt/python/Titanic_Model/AutoML_titanic/params.json'
2021-08-11 07:51:05,909 titanic ERROR Exception on /api/preObject [GET]
Traceback (most recent call last):
  File "/var/lib/jenkins/.local/lib/python3.7/site-packages/supervised/base_automl.py", line 133, in load
    params = json.load(open(os.path.join(path, "params.json")))
FileNotFoundError: [Errno 2] No such file or directory: '/opt/python/Titanic_Model/AutoML_titanic/params.json'

During handling of the above exception, another exception occurred:

Traceback (most recent call last):
  File "/usr/local/lib/python3.7/dist-packages/flask/app.py", line 2070, in wsgi_app
    response = self.full_dispatch_request()
  File "/usr/local/lib/python3.7/dist-packages/flask/app.py", line 1515, in full_dispatch_request
    rv = self.handle_user_exception(e)
  File "/usr/local/lib/python3.7/dist-packages/flask/app.py", line 1513, in full_dispatch_request
    rv = self.dispatch_request()
  File "/usr/local/lib/python3.7/dist-packages/flask/app.py", line 1499, in dispatch_request
    return self.ensure_sync(self.view_functions[rule.endpoint])(**req.view_args)
  File "titanic.py", line 35, in predictobject
    predictions = automl.predict(test)
  File "/var/lib/jenkins/.local/lib/python3.7/site-packages/supervised/automl.py", line 356, in predict
    return self._predict(X)
  File "/var/lib/jenkins/.local/lib/python3.7/site-packages/supervised/base_automl.py", line 1306, in _predict
    predictions = self._base_predict(X)
  File "/var/lib/jenkins/.local/lib/python3.7/site-packages/supervised/base_automl.py", line 1238, in _base_predict
    self.load(self.results_path)
  File "/var/lib/jenkins/.local/lib/python3.7/site-packages/supervised/base_automl.py", line 219, in load
    raise AutoMLException(f"Cannot load AutoML directory. {str(e)}")
supervised.exceptions.AutoMLException: Cannot load AutoML directory. [Errno 2] No such file or directory: '/opt/python/Titanic_Model/AutoML_titanic/params.json'
2021-08-11 07:51:05,909 werkzeug INFO 127.0.0.1 - - [11/Aug/2021 07:51:05] "[35m[1mGET /api/preObject HTTP/1.1[0m" 500 -
2021-08-11 07:51:12,406 werkzeug INFO 127.0.0.1 - - [11/Aug/2021 07:51:12] "GET /api/predict HTTP/1.1" 200 -
2021-08-11 07:54:28,233 supervised.exceptions ERROR Cannot load AutoML directory. [Errno 2] No such file or directory: '/opt/python/Titanic_Model/AutoML_titanic/params.json'
2021-08-11 07:54:28,233 titanic ERROR Exception on /api/preObject [GET]
Traceback (most recent call last):
  File "/var/lib/jenkins/.local/lib/python3.7/site-packages/supervised/base_automl.py", line 133, in load
    params = json.load(open(os.path.join(path, "params.json")))
FileNotFoundError: [Errno 2] No such file or directory: '/opt/python/Titanic_Model/AutoML_titanic/params.json'

During handling of the above exception, another exception occurred:

Traceback (most recent call last):
  File "/usr/local/lib/python3.7/dist-packages/flask/app.py", line 2070, in wsgi_app
    response = self.full_dispatch_request()
  File "/usr/local/lib/python3.7/dist-packages/flask/app.py", line 1515, in full_dispatch_request
    rv = self.handle_user_exception(e)
  File "/usr/local/lib/python3.7/dist-packages/flask/app.py", line 1513, in full_dispatch_request
    rv = self.dispatch_request()
  File "/usr/local/lib/python3.7/dist-packages/flask/app.py", line 1499, in dispatch_request
    return self.ensure_sync(self.view_functions[rule.endpoint])(**req.view_args)
  File "titanic.py", line 35, in predictobject
    predictions = automl.predict(test)
  File "/var/lib/jenkins/.local/lib/python3.7/site-packages/supervised/automl.py", line 356, in predict
    return self._predict(X)
  File "/var/lib/jenkins/.local/lib/python3.7/site-packages/supervised/base_automl.py", line 1306, in _predict
    predictions = self._base_predict(X)
  File "/var/lib/jenkins/.local/lib/python3.7/site-packages/supervised/base_automl.py", line 1238, in _base_predict
    self.load(self.results_path)
  File "/var/lib/jenkins/.local/lib/python3.7/site-packages/supervised/base_automl.py", line 219, in load
    raise AutoMLException(f"Cannot load AutoML directory. {str(e)}")
supervised.exceptions.AutoMLException: Cannot load AutoML directory. [Errno 2] No such file or directory: '/opt/python/Titanic_Model/AutoML_titanic/params.json'
2021-08-11 07:54:28,234 werkzeug INFO 127.0.0.1 - - [11/Aug/2021 07:54:28] "[35m[1mGET /api/preObject HTTP/1.1[0m" 500 -
2021-08-11 08:15:26,773 werkzeug INFO 127.0.0.1 - - [11/Aug/2021 08:15:26] "GET /api/metrics HTTP/1.1" 200 -
2021-08-11 08:15:50,812 supervised.exceptions ERROR Cannot load AutoML directory. [Errno 2] No such file or directory: '/opt/python/Titanic_Model/AutoML_titanic/params.json'
2021-08-11 08:15:50,812 titanic ERROR Exception on /api/preObject [GET]
Traceback (most recent call last):
  File "/var/lib/jenkins/.local/lib/python3.7/site-packages/supervised/base_automl.py", line 133, in load
    params = json.load(open(os.path.join(path, "params.json")))
FileNotFoundError: [Errno 2] No such file or directory: '/opt/python/Titanic_Model/AutoML_titanic/params.json'

During handling of the above exception, another exception occurred:

Traceback (most recent call last):
  File "/usr/local/lib/python3.7/dist-packages/flask/app.py", line 2070, in wsgi_app
    response = self.full_dispatch_request()
  File "/usr/local/lib/python3.7/dist-packages/flask/app.py", line 1515, in full_dispatch_request
    rv = self.handle_user_exception(e)
  File "/usr/local/lib/python3.7/dist-packages/flask/app.py", line 1513, in full_dispatch_request
    rv = self.dispatch_request()
  File "/usr/local/lib/python3.7/dist-packages/flask/app.py", line 1499, in dispatch_request
    return self.ensure_sync(self.view_functions[rule.endpoint])(**req.view_args)
  File "titanic.py", line 35, in predictobject
    predictions = automl.predict(test)
  File "/var/lib/jenkins/.local/lib/python3.7/site-packages/supervised/automl.py", line 356, in predict
    return self._predict(X)
  File "/var/lib/jenkins/.local/lib/python3.7/site-packages/supervised/base_automl.py", line 1306, in _predict
    predictions = self._base_predict(X)
  File "/var/lib/jenkins/.local/lib/python3.7/site-packages/supervised/base_automl.py", line 1238, in _base_predict
    self.load(self.results_path)
  File "/var/lib/jenkins/.local/lib/python3.7/site-packages/supervised/base_automl.py", line 219, in load
    raise AutoMLException(f"Cannot load AutoML directory. {str(e)}")
supervised.exceptions.AutoMLException: Cannot load AutoML directory. [Errno 2] No such file or directory: '/opt/python/Titanic_Model/AutoML_titanic/params.json'
2021-08-11 08:15:50,813 werkzeug INFO 127.0.0.1 - - [11/Aug/2021 08:15:50] "[35m[1mGET /api/preObject HTTP/1.1[0m" 500 -
 * Serving Flask app 'titanic' (lazy loading)
 * Environment: production
   WARNING: This is a development server. Do not use it in a production deployment.
   Use a production WSGI server instead.
 * Debug mode: off
/usr/local/lib/python3.7/dist-packages/numba/errors.py:137: UserWarning: Insufficiently recent colorama version found. Numba requires colorama >= 0.3.9
  warnings.warn(msg)
IPython could not be loaded!
Traceback (most recent call last):
  File "titanic.py", line 56, in <module>
    app.run(host='0.0.0.0',port=5600)
  File "/usr/local/lib/python3.7/dist-packages/flask/app.py", line 922, in run
    run_simple(t.cast(str, host), port, self, **options)
  File "/usr/local/lib/python3.7/dist-packages/werkzeug/serving.py", line 1008, in run_simple
    inner()
  File "/usr/local/lib/python3.7/dist-packages/werkzeug/serving.py", line 957, in inner
    fd=fd,
  File "/usr/local/lib/python3.7/dist-packages/werkzeug/serving.py", line 781, in make_server
    host, port, app, request_handler, passthrough_errors, ssl_context, fd=fd
  File "/usr/local/lib/python3.7/dist-packages/werkzeug/serving.py", line 686, in __init__
    super().__init__(server_address, handler)  # type: ignore
  File "/usr/lib/python3.7/socketserver.py", line 452, in __init__
    self.server_bind()
  File "/usr/lib/python3.7/http/server.py", line 137, in server_bind
    socketserver.TCPServer.server_bind(self)
  File "/usr/lib/python3.7/socketserver.py", line 466, in server_bind
    self.socket.bind(self.server_address)
OSError: [Errno 98] Address already in use
2021-08-11 08:41:49,934 werkzeug INFO 127.0.0.1 - - [11/Aug/2021 08:41:49] "GET /api/train HTTP/1.1" 200 -
2021-08-11 08:42:07,298 supervised.exceptions ERROR Cannot load AutoML directory. [Errno 2] No such file or directory: '/opt/python/Titanic_Model/AutoML_titanic/params.json'
2021-08-11 08:42:07,299 titanic ERROR Exception on /api/preObject [GET]
Traceback (most recent call last):
  File "/var/lib/jenkins/.local/lib/python3.7/site-packages/supervised/base_automl.py", line 133, in load
    params = json.load(open(os.path.join(path, "params.json")))
FileNotFoundError: [Errno 2] No such file or directory: '/opt/python/Titanic_Model/AutoML_titanic/params.json'

During handling of the above exception, another exception occurred:

Traceback (most recent call last):
  File "/usr/local/lib/python3.7/dist-packages/flask/app.py", line 2070, in wsgi_app
    response = self.full_dispatch_request()
  File "/usr/local/lib/python3.7/dist-packages/flask/app.py", line 1515, in full_dispatch_request
    rv = self.handle_user_exception(e)
  File "/usr/local/lib/python3.7/dist-packages/flask/app.py", line 1513, in full_dispatch_request
    rv = self.dispatch_request()
  File "/usr/local/lib/python3.7/dist-packages/flask/app.py", line 1499, in dispatch_request
    return self.ensure_sync(self.view_functions[rule.endpoint])(**req.view_args)
  File "titanic.py", line 35, in predictobject
    predictions = automl.predict(test)
  File "/var/lib/jenkins/.local/lib/python3.7/site-packages/supervised/automl.py", line 356, in predict
    return self._predict(X)
  File "/var/lib/jenkins/.local/lib/python3.7/site-packages/supervised/base_automl.py", line 1306, in _predict
    predictions = self._base_predict(X)
  File "/var/lib/jenkins/.local/lib/python3.7/site-packages/supervised/base_automl.py", line 1238, in _base_predict
    self.load(self.results_path)
  File "/var/lib/jenkins/.local/lib/python3.7/site-packages/supervised/base_automl.py", line 219, in load
    raise AutoMLException(f"Cannot load AutoML directory. {str(e)}")
supervised.exceptions.AutoMLException: Cannot load AutoML directory. [Errno 2] No such file or directory: '/opt/python/Titanic_Model/AutoML_titanic/params.json'
2021-08-11 08:42:07,299 werkzeug INFO 127.0.0.1 - - [11/Aug/2021 08:42:07] "[35m[1mGET /api/preObject HTTP/1.1[0m" 500 -
2021-08-11 08:42:55,061 supervised.exceptions ERROR Cannot load AutoML directory. [Errno 2] No such file or directory: '/opt/python/Titanic_Model/AutoML_titanic/params.json'
2021-08-11 08:42:55,061 titanic ERROR Exception on /api/preObject [GET]
Traceback (most recent call last):
  File "/var/lib/jenkins/.local/lib/python3.7/site-packages/supervised/base_automl.py", line 133, in load
    params = json.load(open(os.path.join(path, "params.json")))
FileNotFoundError: [Errno 2] No such file or directory: '/opt/python/Titanic_Model/AutoML_titanic/params.json'

During handling of the above exception, another exception occurred:

Traceback (most recent call last):
  File "/usr/local/lib/python3.7/dist-packages/flask/app.py", line 2070, in wsgi_app
    response = self.full_dispatch_request()
  File "/usr/local/lib/python3.7/dist-packages/flask/app.py", line 1515, in full_dispatch_request
    rv = self.handle_user_exception(e)
  File "/usr/local/lib/python3.7/dist-packages/flask/app.py", line 1513, in full_dispatch_request
    rv = self.dispatch_request()
  File "/usr/local/lib/python3.7/dist-packages/flask/app.py", line 1499, in dispatch_request
    return self.ensure_sync(self.view_functions[rule.endpoint])(**req.view_args)
  File "titanic.py", line 35, in predictobject
    predictions = automl.predict(test)
  File "/var/lib/jenkins/.local/lib/python3.7/site-packages/supervised/automl.py", line 356, in predict
    return self._predict(X)
  File "/var/lib/jenkins/.local/lib/python3.7/site-packages/supervised/base_automl.py", line 1306, in _predict
    predictions = self._base_predict(X)
  File "/var/lib/jenkins/.local/lib/python3.7/site-packages/supervised/base_automl.py", line 1238, in _base_predict
    self.load(self.results_path)
  File "/var/lib/jenkins/.local/lib/python3.7/site-packages/supervised/base_automl.py", line 219, in load
    raise AutoMLException(f"Cannot load AutoML directory. {str(e)}")
supervised.exceptions.AutoMLException: Cannot load AutoML directory. [Errno 2] No such file or directory: '/opt/python/Titanic_Model/AutoML_titanic/params.json'
2021-08-11 08:42:55,061 werkzeug INFO 127.0.0.1 - - [11/Aug/2021 08:42:55] "[35m[1mGET /api/preObject HTTP/1.1[0m" 500 -
2021-08-11 08:56:37,959 supervised.exceptions ERROR Cannot load AutoML directory. [Errno 2] No such file or directory: '/opt/python/Titanic_Model/AutoML_titanic/params.json'
2021-08-11 08:56:37,959 titanic ERROR Exception on /api/preObject [GET]
Traceback (most recent call last):
  File "/var/lib/jenkins/.local/lib/python3.7/site-packages/supervised/base_automl.py", line 133, in load
    params = json.load(open(os.path.join(path, "params.json")))
FileNotFoundError: [Errno 2] No such file or directory: '/opt/python/Titanic_Model/AutoML_titanic/params.json'

During handling of the above exception, another exception occurred:

Traceback (most recent call last):
  File "/usr/local/lib/python3.7/dist-packages/flask/app.py", line 2070, in wsgi_app
    response = self.full_dispatch_request()
  File "/usr/local/lib/python3.7/dist-packages/flask/app.py", line 1515, in full_dispatch_request
    rv = self.handle_user_exception(e)
  File "/usr/local/lib/python3.7/dist-packages/flask/app.py", line 1513, in full_dispatch_request
    rv = self.dispatch_request()
  File "/usr/local/lib/python3.7/dist-packages/flask/app.py", line 1499, in dispatch_request
    return self.ensure_sync(self.view_functions[rule.endpoint])(**req.view_args)
  File "titanic.py", line 35, in predictobject
    predictions = automl.predict(test)
  File "/var/lib/jenkins/.local/lib/python3.7/site-packages/supervised/automl.py", line 356, in predict
    return self._predict(X)
  File "/var/lib/jenkins/.local/lib/python3.7/site-packages/supervised/base_automl.py", line 1306, in _predict
    predictions = self._base_predict(X)
  File "/var/lib/jenkins/.local/lib/python3.7/site-packages/supervised/base_automl.py", line 1238, in _base_predict
    self.load(self.results_path)
  File "/var/lib/jenkins/.local/lib/python3.7/site-packages/supervised/base_automl.py", line 219, in load
    raise AutoMLException(f"Cannot load AutoML directory. {str(e)}")
supervised.exceptions.AutoMLException: Cannot load AutoML directory. [Errno 2] No such file or directory: '/opt/python/Titanic_Model/AutoML_titanic/params.json'
2021-08-11 08:56:37,960 werkzeug INFO 127.0.0.1 - - [11/Aug/2021 08:56:37] "[35m[1mGET /api/preObject HTTP/1.1[0m" 500 -
2021-08-11 09:05:45,673 werkzeug INFO 127.0.0.1 - - [11/Aug/2021 09:05:45] "GET /api/train HTTP/1.1" 200 -
